Workbook

Sheet BÌA SỔ SL (9)
A1: VIETNAM RUBBER GROUP
A2: CHU SE - KAMPONG THOM RUBBER JSC
A3: C.R.C.K.2 APHIVATH CAOUTCHOUC CO.,LTD
A4: --------------*****--------------
A8: TRACKING PRODUCTION YIELD OF FIELD GRDE COAGULUM FORM
A9: SỔ THEO DÕI SẢN LƯỢNG NĂM 2026
A10: FARM UNIT/ ĐỘI SẢN XUẤT: 01
A11: Area/ Diện tích: 209.79
A12: ADDRESS: PHTEAH DAEUM VILLAGE, PO POK COMMUNE, STOUNG DISTRICT, KAMPONG THOM PROVINCE, CAMBODIA.
E13: ZONE/Khu vực: 09
A18: Kampong Thom, Month 1 Year 2026
A19: Kampong Thom, Tháng 1 năm 2026

Sheet BÌA SỔ SL (8)
A1: VIETNAM RUBBER GROUP
A2: CHU SE - KAMPONG THOM RUBBER JSC
A3: C.R.C.K.2 APHIVATH CAOUTCHOUC CO.,LTD
A4: --------------*****--------------
A8: TRACKING PRODUCTION YIELD OF FIELD GRDE COAGULUM FORM
A9: SỔ THEO DÕI SẢN LƯỢNG NĂM 2026
A10: FARM UNIT/ ĐỘI SẢN XUẤT: 01
A11: Area/ Diện tích: 209.38
A12: ADDRESS: PHTEAH DAEUM VILLAGE, PO POK COMMUNE, STOUNG DISTRICT, KAMPONG THOM PROVINCE, CAMBODIA.
E13: ZONE/Khu vực: 08
A18: Kampong Thom, Month 1 Year 2026
A19: Kampong Thom, Tháng 1 năm 2026

Sheet BÌA SỔ SL (7)
A1: VIETNAM RUBBER GROUP
A2: CHU SE - KAMPONG THOM RUBBER JSC
A3: C.R.C.K.2 APHIVATH CAOUTCHOUC CO.,LTD
A4: --------------*****--------------
A8: TRACKING PRODUCTION YIELD OF FIELD GRDE COAGULUM FORM
A9: SỔ THEO DÕI SẢN LƯỢNG NĂM 2026
A10: FARM UNIT/ ĐỘI SẢN XUẤT: 01
A11: Area/ Diện tích: 232.52
A12: ADDRESS: PHTEAH DAEUM VILLAGE, PO POK COMMUNE, STOUNG DISTRICT, KAMPONG THOM PROVINCE, CAMBODIA.
E13: ZONE/Khu vực: 07
A18: Kampong Thom, Month 1 Year 2026
A19: Kampong Thom, Tháng 1 năm 2026

Sheet BÌA SỔ SL (6)
A1: VIETNAM RUBBER GROUP
A2: CHU SE - KAMPONG THOM RUBBER JSC
A3: C.R.C.K.2 APHIVATH CAOUTCHOUC CO.,LTD
A4: --------------*****--------------
A8: TRACKING PRODUCTION YIELD OF FIELD GRDE COAGULUM FORM
A9: SỔ THEO DÕI SẢN LƯỢNG NĂM 2026
A10: FARM UNIT/ ĐỘI SẢN XUẤT: 01
A11: Area/ Diện tích: 267.36
A12: ADDRESS: PHTEAH DAEUM VILLAGE, PO POK COMMUNE, STOUNG DISTRICT, KAMPONG THOM PROVINCE, CAMBODIA.
E13: ZONE/Khu vực: 06
A18: Kampong Thom, Month 1 Year 2026
A19: Kampong Thom, Tháng 1 năm 2026

Sheet BÌA SỔ SL (5)
A1: VIETNAM RUBBER GROUP
A2: CHU SE - KAMPONG THOM RUBBER JSC
A3: C.R.C.K.2 APHIVATH CAOUTCHOUC CO.,LTD
A4: --------------*****--------------
A8: TRACKING PRODUCTION YIELD OF FIELD GRDE COAGULUM FORM
A9: SỔ THEO DÕI SẢN LƯỢNG NĂM 2026
A10: FARM UNIT/ ĐỘI SẢN XUẤT: 01
A11: Area/ Diện tích: 240.44
A12: ADDRESS: PHTEAH DAEUM VILLAGE, PO POK COMMUNE, STOUNG DISTRICT, KAMPONG THOM PROVINCE, CAMBODIA.
E13: ZONE/Khu vực: 05
A18: Kampong Thom, Month 1 Year 2026
A19: Kampong Thom, Tháng 1 năm 2026

Sheet BÌA SỔ SL (4)
A1: VIETNAM RUBBER GROUP
A2: CHU SE - KAMPONG THOM RUBBER JSC
A3: C.R.C.K.2 APHIVATH CAOUTCHOUC CO.,LTD
A4: --------------*****--------------
A8: TRACKING PRODUCTION YIELD OF FIELD GRDE COAGULUM FORM
A9: SỔ THEO DÕI SẢN LƯỢNG NĂM 2026
A10: FARM UNIT/ ĐỘI SẢN XUẤT: 01
A11: Area/ Diện tích: 250.44
A12: ADDRESS: PHTEAH DAEUM VILLAGE, PO POK COMMUNE, STOUNG DISTRICT, KAMPONG THOM PROVINCE, CAMBODIA.
E13: ZONE/Khu vực: 04
A18: Kampong Thom, Month 1 Year 2026
A19: Kampong Thom, Tháng 1 năm 2026

Sheet BÌA SỔ SL (3)
A1: VIETNAM RUBBER GROUP
A2: CHU SE - KAMPONG THOM RUBBER JSC
A3: C.R.C.K.2 APHIVATH CAOUTCHOUC CO.,LTD
A4: --------------*****--------------
A8: TRACKING PRODUCTION YIELD OF FIELD GRDE COAGULUM FORM
A9: SỔ THEO DÕI SẢN LƯỢNG NĂM 2026
A10: FARM UNIT/ ĐỘI SẢN XUẤT: 01
A11: Area/ Diện tích: 251.42
A12: ADDRESS: PHTEAH DAEUM VILLAGE, PO POK COMMUNE, STOUNG DISTRICT, KAMPONG THOM PROVINCE, CAMBODIA.
E13: ZONE/Khu vực: 03
A18: Kampong Thom, Month 1 Year 2026
A19: Kampong Thom, Tháng 1 năm 2026

Sheet BÌA SỔ SL (2)
A1: VIETNAM RUBBER GROUP
A2: CHU SE - KAMPONG THOM RUBBER JSC
A3: C.R.C.K.2 APHIVATH CAOUTCHOUC CO.,LTD
A4: --------------*****--------------
A8: TRACKING PRODUCTION YIELD OF FIELD GRDE COAGULUM FORM
A9: SỔ THEO DÕI SẢN LƯỢNG NĂM 2026
A10: FARM UNIT/ ĐỘI SẢN XUẤT: 01
A11: Area/ Diện tích: 249.17
A12: ADDRESS: PHTEAH DAEUM VILLAGE, PO POK COMMUNE, STOUNG DISTRICT, KAMPONG THOM PROVINCE, CAMBODIA.
E13: ZONE/Khu vực: 02
A18: Kampong Thom, Month 1 Year 2026
A19: Kampong Thom, Tháng 1 năm 2026

Sheet BÌA SỔ SL
A1: VIETNAM RUBBER GROUP
A2: CHU SE - KAMPONG THOM RUBBER JSC
A3: C.R.C.K.2 APHIVATH CAOUTCHOUC CO.,LTD
A4: --------------*****--------------
A8: TRACKING PRODUCTION YIELD OF FIELD GRDE COAGULUM FORM
A9: SỔ THEO DÕI SẢN LƯỢNG NĂM 2026
A10: FARM UNIT/ ĐỘI SẢN XUẤT: 01
A11: Area/ Diện tích: 263.11
A12: ADDRESS: PHTEAH DAEUM VILLAGE, PO POK COMMUNE, STOUNG DISTRICT, KAMPONG THOM PROVINCE, CAMBODIA.
E13: ZONE/Khu vực: 01
A18: Kampong Thom, Month 1 Year 2026
A19: Kampong Thom, Tháng 1 năm 2026

Sheet T1
A1: Yield for the month 1/2026 / SẢN LƯỢNG THÁNG 1 NĂM 2026
A2: No. | B2: Forest Plot Code | C2: Name of Plot | D2: Full Name | E2: Employee ID | F2: Date / Ngày ........... | H2: Date / Ngày ........... | J2: Date / Ngày ........... | L2: Date / Ngày ........... | N2: Date / Ngày ........... | P2: Date / Ngày ........... | R2: Date / Ngày ........... | T2: Date / Ngày ........... | V2: Total Days
V3: TỔNG 0 NGÀY
A4: STT | B4: Mã lô rừng | C4: Tên lô | D4: HỌ VÀ TÊN | E4: Mã số CN | F4: Tapp. Session/ Phiên cạo A | H4: Tapp. Session/ Phiên cạo A | J4: Tapp. Session/ Phiên cạo A | L4: Tapp. Session/ Phiên cạo A | N4: Tapp. Session/ Phiên cạo A | P4: Tapp. Session/ Phiên cạo A | R4: Tapp. Session/ Phiên cạo A | T4: Tapp. Session/ Phiên cạo A | V4: From…..top …...
V5: (Từ ngày…...đến ngày.…..)
F6: Cup Lump | H6: Cup Lump | J6: Cup Lump | L6: Cup Lump | N6: Cup Lump | P6: Cup Lump | R6: Cup Lump | T6: Cup Lump | V6: Cup Lump
F7: Mủ đông | H7: Mủ đông | J7: Mủ đông | L7: Mủ đông | N7: Mủ đông | P7: Mủ đông | R7: Mủ đông | T7: Mủ đông | V7: Mủ đông
V8: =SUM(F8:U8)
A9: Total / TC | F9: =SUM(F8:F8) | H9: =SUM(H8:H8) | J9: =SUM(J8:J8) | L9: =SUM(L8:L8) | N9: =SUM(N8:N8) | P9: =SUM(P8:P8) | R9: =SUM(R8:R8) | T9: =SUM(T8:T8) | V9: =SUBTOTAL(9,V8:V8)
A11: Notes/ GHI CHÚ:
A13: Đ: Đạt - mủ loại 1 đạt chất lượng : Có hình dáng theo dụng cụ chứa (chén, thùng) thường là hình trụ. Có màu trắng, vàng, không lẫn các tạp chất dễ thấy như lá cây, vỏ cây, sợi PP, kim loại, côn trùng, đất cát và các tạp chất khác
A14: Grade 1 :FGC characteristics: Shape :conform to the Shape of container(cup, buckest). Color :White, Yellow. Impurities : No no visible impurities such as leaves, bark, PP fibers, metal, insects, dirt, sand, or other foreign matter
A15: KĐ: Không đạt - mủ loại 2 không đạt chất lượng : Có hình dáng theo dụng cụ chứa (chén, thùng) thường là hình trụ. Có lẫn các tạp chất dễ thấy như lá cây, vỏ cây, sợi PP, kim loại, côn trùng, đất cát và các tạp chất khác.
A16: Grade 2 :FGC characteristics: Shape :conform to the Shape of container(cup, buckest). . Impurities: It contains visible impurities such as leaves, bark, PP fibers, metal, insects, dirt, sand, and other foreign matte
A17: …………….……….....………..….…………………..……………...…………..…………………………...……..…………...………………………………..........................................................................................................................................................................................................................................
A18: …………….……….....………..….…………………..……………...…………..…………………………...……..…………...………………………………..........................................................................................................................................................................................................................................
A19: …………….……….....………..….…………………..……………...…………..…………………………...……..…………...………………………………..........................................................................................................................................................................................................................................
A22: Yield for the month 1/2026 / SẢN LƯỢNG THÁNG 1 NĂM 2026
A23: No. | B23: Forest Plot Code | C23: Name of Plot | D23: Full Name | E23: Employee ID | F23: Date / Ngày ........... | H23: Date / Ngày ........... | J23: Date / Ngày ........... | L23: Date / Ngày ........... | N23: Date / Ngày ........... | P23: Date / Ngày ........... | R23: Date / Ngày ........... | T23: Date / Ngày ........... | V23: Total Days
V24: TỔNG 0 NGÀY
A25: STT | B25: Mã lô rừng | C25: Tên lô | D25: HỌ VÀ TÊN | E25: Mã số CN | F25: Tapp. Session/ Phiên cạo B | H25: Tapp. Session/ Phiên cạo B | J25: Tapp. Session/ Phiên cạo B | L25: Tapp. Session/ Phiên cạo B | N25: Tapp. Session/ Phiên cạo B | P25: Tapp. Session/ Phiên cạo B | R25: Tapp. Session/ Phiên cạo B | T25: Tapp. Session/ Phiên cạo B | V25: From…..top …...
V26: (Từ ngày…...đến ngày.…..)
F27: Cup Lump | H27: Cup Lump | J27: Cup Lump | L27: Cup Lump | N27: Cup Lump | P27: Cup Lump | R27: Cup Lump | T27: Cup Lump | V27: Cup Lump
F28: Mủ đông | H28: Mủ đông | J28: Mủ đông | L28: Mủ đông | N28: Mủ đông | P28: Mủ đông | R28: Mủ đông | T28: Mủ đông | V28: Mủ đông
V29: =SUM(F29:U29)
A30: Total / TC | F30: =SUM(F29:F29) | H30: =SUM(H29:H29) | J30: =SUM(J29:J29) | L30: =SUM(L29:L29) | N30: =SUM(N29:N29) | P30: =SUM(P29:P29) | R30: =SUM(R29:R29) | T30: =SUM(T29:T29) | V30: =SUBTOTAL(9,V29:V29)
A32: Notes/ GHI CHÚ:
A34: Đ: Đạt - mủ loại 1 đạt chất lượng : Có hình dáng theo dụng cụ chứa (chén, thùng) thường là hình trụ. Có màu trắng, vàng, không lẫn các tạp chất dễ thấy như lá cây, vỏ cây, sợi PP, kim loại, côn trùng, đất cát và các tạp chất khác
A35: Grade 1 :FGC characteristics: Shape :conform to the Shape of container(cup, buckest). Color :White, Yellow. Impurities : No no visible impurities such as leaves, bark, PP fibers, metal, insects, dirt, sand, or other foreign matter
A36: KĐ: Không đạt - mủ loại 2 không đạt chất lượng : Có hình dáng theo dụng cụ chứa (chén, thùng) thường là hình trụ. Có lẫn các tạp chất dễ thấy như lá cây, vỏ cây, sợi PP, kim loại, côn trùng, đất cát và các tạp chất khác.
A37: Grade 2 :FGC characteristics: Shape :conform to the Shape of container(cup, buckest). . Impurities: It contains visible impurities such as leaves, bark, PP fibers, metal, insects, dirt, sand, and other foreign matte
A38: …………….……….....………..….…………………..……………...…………..…………………………...……..…………...………………………………..........................................................................................................................................................................................................................................
A39: …………….……….....………..….…………………..……………...…………..…………………………...……..…………...………………………………..........................................................................................................................................................................................................................................
A40: …………….……….....………..….…………………..……………...…………..…………………………...……..…………...………………………………..........................................................................................................................................................................................................................................
A43: Yield for the month 1/2026 / SẢN LƯỢNG THÁNG 1 NĂM 2026
A44: No. | B44: Forest Plot Code | C44: Name of Plot | D44: Full Name | E44: Employee ID | F44: Date / Ngày ........... | H44: Date / Ngày ........... | J44: Date / Ngày ........... | L44: Date / Ngày ........... | N44: Date / Ngày ........... | P44: Date / Ngày ........... | R44: Date / Ngày ........... | T44: Date / Ngày ........... | V44: Total Days
V45: TỔNG 0 NGÀY
A46: STT | B46: Mã lô rừng | C46: Tên lô | D46: HỌ VÀ TÊN | E46: Mã số CN | F46: Tapp. Session/ Phiên cạo C | H46: Tapp. Session/ Phiên cạo C | J46: Tapp. Session/ Phiên cạo C | L46: Tapp. Session/ Phiên cạo C | N46: Tapp. Session/ Phiên cạo C | P46: Tapp. Session/ Phiên cạo C | R46: Tapp. Session/ Phiên cạo C | T46: Tapp. Session/ Phiên cạo C | V46: From…..top …...
V47: (Từ ngày…...đến ngày.…..)
F48: Cup Lump | H48: Cup Lump | J48: Cup Lump | L48: Cup Lump | N48: Cup Lump | P48: Cup Lump | R48: Cup Lump | T48: Cup Lump | V48: Cup Lump
...

Sheet T2
A1: Yield for the month 1/2026 / SẢN LƯỢNG THÁNG 1 NĂM 2026
A2: No. | B2: Forest Plot Code | C2: Name of Plot | D2: Full Name | E2: Employee ID | F2: Date / Ngày ........... | H2: Date / Ngày ........... | J2: Date / Ngày ........... | L2: Date / Ngày ........... | N2: Date / Ngày ........... | P2: Date / Ngày ........... | R2: Date / Ngày ........... | T2: Date / Ngày ........... | V2: Total Days
V3: TỔNG 0 NGÀY
A4: STT | B4: Mã lô rừng | C4: Tên lô | D4: HỌ VÀ TÊN | E4: Mã số CN | F4: Tapp. Session/ Phiên cạo A | H4: Tapp. Session/ Phiên cạo A | J4: Tapp. Session/ Phiên cạo A | L4: Tapp. Session/ Phiên cạo A | N4: Tapp. Session/ Phiên cạo A | P4: Tapp. Session/ Phiên cạo A | R4: Tapp. Session/ Phiên cạo A | T4: Tapp. Session/ Phiên cạo A | V4: From…..top …...
V5: (Từ ngày…...đến ngày.…..)
F6: Cup Lump | H6: Cup Lump | J6: Cup Lump | L6: Cup Lump | N6: Cup Lump | P6: Cup Lump | R6: Cup Lump | T6: Cup Lump | V6: Cup Lump
F7: Mủ đông | H7: Mủ đông | J7: Mủ đông | L7: Mủ đông | N7: Mủ đông | P7: Mủ đông | R7: Mủ đông | T7: Mủ đông | V7: Mủ đông
V8: =SUM(F8:U8)
A9: Total / TC | F9: =SUM(F8:F8) | H9: =SUM(H8:H8) | J9: =SUM(J8:J8) | L9: =SUM(L8:L8) | N9: =SUM(N8:N8) | P9: =SUM(P8:P8) | R9: =SUM(R8:R8) | T9: =SUM(T8:T8) | V9: =SUBTOTAL(9,V8:V8)
A11: Notes/ GHI CHÚ:
A13: Đ: Đạt - mủ loại 1 đạt chất lượng : Có hình dáng theo dụng cụ chứa (chén, thùng) thường là hình trụ. Có màu trắng, vàng, không lẫn các tạp chất dễ thấy như lá cây, vỏ cây, sợi PP, kim loại, côn trùng, đất cát và các tạp chất khác
A14: Grade 1 :FGC characteristics: Shape :conform to the Shape of container(cup, buckest). Color :White, Yellow. Impurities : No no visible impurities such as leaves, bark, PP fibers, metal, insects, dirt, sand, or other foreign matter
A15: KĐ: Không đạt - mủ loại 2 không đạt chất lượng : Có hình dáng theo dụng cụ chứa (chén, thùng) thường là hình trụ. Có lẫn các tạp chất dễ thấy như lá cây, vỏ cây, sợi PP, kim loại, côn trùng, đất cát và các tạp chất khác.
A16: Grade 2 :FGC characteristics: Shape :conform to the Shape of container(cup, buckest). . Impurities: It contains visible impurities such as leaves, bark, PP fibers, metal, insects, dirt, sand, and other foreign matte
A17: …………….……….....………..….…………………..……………...…………..…………………………...……..…………...………………………………..........................................................................................................................................................................................................................................
A18: …………….……….....………..….…………………..……………...…………..…………………………...……..…………...………………………………..........................................................................................................................................................................................................................................
A19: …………….……….....………..….…………………..……………...…………..…………………………...……..…………...………………………………..........................................................................................................................................................................................................................................
A22: Yield for the month 1/2026 / SẢN LƯỢNG THÁNG 1 NĂM 2026
A23: No. | B23: Forest Plot Code | C23: Name of Plot | D23: Full Name | E23: Employee ID | F23: Date / Ngày ........... | H23: Date / Ngày ........... | J23: Date / Ngày ........... | L23: Date / Ngày ........... | N23: Date / Ngày ........... | P23: Date / Ngày ........... | R23: Date / Ngày ........... | T23: Date / Ngày ........... | V23: Total Days
V24: TỔNG 0 NGÀY
A25: STT | B25: Mã lô rừng | C25: Tên lô | D25: HỌ VÀ TÊN | E25: Mã số CN | F25: Tapp. Session/ Phiên cạo B | H25: Tapp. Session/ Phiên cạo B | J25: Tapp. Session/ Phiên cạo B | L25: Tapp. Session/ Phiên cạo B | N25: Tapp. Session/ Phiên cạo B | P25: Tapp. Session/ Phiên cạo B | R25: Tapp. Session/ Phiên cạo B | T25: Tapp. Session/ Phiên cạo B | V25: From…..top …...
V26: (Từ ngày…...đến ngày.…..)
F27: Cup Lump | H27: Cup Lump | J27: Cup Lump | L27: Cup Lump | N27: Cup Lump | P27: Cup Lump | R27: Cup Lump | T27: Cup Lump | V27: Cup Lump
F28: Mủ đông | H28: Mủ đông | J28: Mủ đông | L28: Mủ đông | N28: Mủ đông | P28: Mủ đông | R28: Mủ đông | T28: Mủ đông | V28: Mủ đông
V29: =SUM(F29:U29)
A30: Total / TC | F30: =SUM(F29:F29) | H30: =SUM(H29:H29) | J30: =SUM(J29:J29) | L30: =SUM(L29:L29) | N30: =SUM(N29:N29) | P30: =SUM(P29:P29) | R30: =SUM(R29:R29) | T30: =SUM(T29:T29) | V30: =SUBTOTAL(9,V29:V29)
A32: Notes/ GHI CHÚ:
A34: Đ: Đạt - mủ loại 1 đạt chất lượng : Có hình dáng theo dụng cụ chứa (chén, thùng) thường là hình trụ. Có màu trắng, vàng, không lẫn các tạp chất dễ thấy như lá cây, vỏ cây, sợi PP, kim loại, côn trùng, đất cát và các tạp chất khác
A35: Grade 1 :FGC characteristics: Shape :conform to the Shape of container(cup, buckest). Color :White, Yellow. Impurities : No no visible impurities such as leaves, bark, PP fibers, metal, insects, dirt, sand, or other foreign matter
A36: KĐ: Không đạt - mủ loại 2 không đạt chất lượng : Có hình dáng theo dụng cụ chứa (chén, thùng) thường là hình trụ. Có lẫn các tạp chất dễ thấy như lá cây, vỏ cây, sợi PP, kim loại, côn trùng, đất cát và các tạp chất khác.
A37: Grade 2 :FGC characteristics: Shape :conform to the Shape of container(cup, buckest). . Impurities: It contains visible impurities such as leaves, bark, PP fibers, metal, insects, dirt, sand, and other foreign matte
A38: …………….……….....………..….…………………..……………...…………..…………………………...……..…………...………………………………..........................................................................................................................................................................................................................................
A39: …………….……….....………..….…………………..……………...…………..…………………………...……..…………...………………………………..........................................................................................................................................................................................................................................
A40: …………….……….....………..….…………………..……………...…………..…………………………...……..…………...………………………………..........................................................................................................................................................................................................................................
A43: Yield for the month 1/2026 / SẢN LƯỢNG THÁNG 1 NĂM 2026
A44: No. | B44: Forest Plot Code | C44: Name of Plot | D44: Full Name | E44: Employee ID | F44: Date / Ngày ........... | H44: Date / Ngày ........... | J44: Date / Ngày ........... | L44: Date / Ngày ........... | N44: Date / Ngày ........... | P44: Date / Ngày ........... | R44: Date / Ngày ........... | T44: Date / Ngày ........... | V44: Total Days
V45: TỔNG 0 NGÀY
A46: STT | B46: Mã lô rừng | C46: Tên lô | D46: HỌ VÀ TÊN | E46: Mã số CN | F46: Tapp. Session/ Phiên cạo C | H46: Tapp. Session/ Phiên cạo C | J46: Tapp. Session/ Phiên cạo C | L46: Tapp. Session/ Phiên cạo C | N46: Tapp. Session/ Phiên cạo C | P46: Tapp. Session/ Phiên cạo C | R46: Tapp. Session/ Phiên cạo C | T46: Tapp. Session/ Phiên cạo C | V46: From…..top …...
V47: (Từ ngày…...đến ngày.…..)
F48: Cup Lump | H48: Cup Lump | J48: Cup Lump | L48: Cup Lump | N48: Cup Lump | P48: Cup Lump | R48: Cup Lump | T48: Cup Lump | V48: Cup Lump
...

Sheet T3
A1: Yield for the month 1/2026 / SẢN LƯỢNG THÁNG 1 NĂM 2026
A2: No. | B2: Forest Plot Code | C2: Name of Plot | D2: Full Name | E2: Employee ID | F2: Date / Ngày ........... | H2: Date / Ngày ........... | J2: Date / Ngày ........... | L2: Date / Ngày ........... | N2: Date / Ngày ........... | P2: Date / Ngày ........... | R2: Date / Ngày ........... | T2: Date / Ngày ........... | V2: Total Days
V3: TỔNG 0 NGÀY
A4: STT | B4: Mã lô rừng | C4: Tên lô | D4: HỌ VÀ TÊN | E4: Mã số CN | F4: Tapp. Session/ Phiên cạo A | H4: Tapp. Session/ Phiên cạo A | J4: Tapp. Session/ Phiên cạo A | L4: Tapp. Session/ Phiên cạo A | N4: Tapp. Session/ Phiên cạo A | P4: Tapp. Session/ Phiên cạo A | R4: Tapp. Session/ Phiên cạo A | T4: Tapp. Session/ Phiên cạo A | V4: From…..top …...
V5: (Từ ngày…...đến ngày.…..)
F6: Cup Lump | H6: Cup Lump | J6: Cup Lump | L6: Cup Lump | N6: Cup Lump | P6: Cup Lump | R6: Cup Lump | T6: Cup Lump | V6: Cup Lump
F7: Mủ đông | H7: Mủ đông | J7: Mủ đông | L7: Mủ đông | N7: Mủ đông | P7: Mủ đông | R7: Mủ đông | T7: Mủ đông | V7: Mủ đông
V8: =SUM(F8:U8)
A9: Total / TC | F9: =SUM(F8:F8) | H9: =SUM(H8:H8) | J9: =SUM(J8:J8) | L9: =SUM(L8:L8) | N9: =SUM(N8:N8) | P9: =SUM(P8:P8) | R9: =SUM(R8:R8) | T9: =SUM(T8:T8) | V9: =SUBTOTAL(9,V8:V8)
A11: Notes/ GHI CHÚ:
A13: Đ: Đạt - mủ loại 1 đạt chất lượng : Có hình dáng theo dụng cụ chứa (chén, thùng) thường là hình trụ. Có màu trắng, vàng, không lẫn các tạp chất dễ thấy như lá cây, vỏ cây, sợi PP, kim loại, côn trùng, đất cát và các tạp chất khác
A14: Grade 1 :FGC characteristics: Shape :conform to the Shape of container(cup, buckest). Color :White, Yellow. Impurities : No no visible impurities such as leaves, bark, PP fibers, metal, insects, dirt, sand, or other foreign matter
A15: KĐ: Không đạt - mủ loại 2 không đạt chất lượng : Có hình dáng theo dụng cụ chứa (chén, thùng) thường là hình trụ. Có lẫn các tạp chất dễ thấy như lá cây, vỏ cây, sợi PP, kim loại, côn trùng, đất cát và các tạp chất khác.
A16: Grade 2 :FGC characteristics: Shape :conform to the Shape of container(cup, buckest). . Impurities: It contains visible impurities such as leaves, bark, PP fibers, metal, insects, dirt, sand, and other foreign matte
A17: …………….……….....………..….…………………..……………...…………..…………………………...……..…………...………………………………..........................................................................................................................................................................................................................................
A18: …………….……….....………..….…………………..……………...…………..…………………………...……..…………...………………………………..........................................................................................................................................................................................................................................
A19: …………….……….....………..….…………………..……………...…………..…………………………...……..…………...………………………………..........................................................................................................................................................................................................................................
A22: Yield for the month 1/2026 / SẢN LƯỢNG THÁNG 1 NĂM 2026
A23: No. | B23: Forest Plot Code | C23: Name of Plot | D23: Full Name | E23: Employee ID | F23: Date / Ngày ........... | H23: Date / Ngày ........... | J23: Date / Ngày ........... | L23: Date / Ngày ........... | N23: Date / Ngày ........... | P23: Date / Ngày ........... | R23: Date / Ngày ........... | T23: Date / Ngày ........... | V23: Total Days
V24: TỔNG 0 NGÀY
A25: STT | B25: Mã lô rừng | C25: Tên lô | D25: HỌ VÀ TÊN | E25: Mã số CN | F25: Tapp. Session/ Phiên cạo B | H25: Tapp. Session/ Phiên cạo B | J25: Tapp. Session/ Phiên cạo B | L25: Tapp. Session/ Phiên cạo B | N25: Tapp. Session/ Phiên cạo B | P25: Tapp. Session/ Phiên cạo B | R25: Tapp. Session/ Phiên cạo B | T25: Tapp. Session/ Phiên cạo B | V25: From…..top …...
V26: (Từ ngày…...đến ngày.…..)
F27: Cup Lump | H27: Cup Lump | J27: Cup Lump | L27: Cup Lump | N27: Cup Lump | P27: Cup Lump | R27: Cup Lump | T27: Cup Lump | V27: Cup Lump
F28: Mủ đông | H28: Mủ đông | J28: Mủ đông | L28: Mủ đông | N28: Mủ đông | P28: Mủ đông | R28: Mủ đông | T28: Mủ đông | V28: Mủ đông
V29: =SUM(F29:U29)
A30: Total / TC | F30: =SUM(F29:F29) | H30: =SUM(H29:H29) | J30: =SUM(J29:J29) | L30: =SUM(L29:L29) | N30: =SUM(N29:N29) | P30: =SUM(P29:P29) | R30: =SUM(R29:R29) | T30: =SUM(T29:T29) | V30: =SUBTOTAL(9,V29:V29)
A32: Notes/ GHI CHÚ:
A34: Đ: Đạt - mủ loại 1 đạt chất lượng : Có hình dáng theo dụng cụ chứa (chén, thùng) thường là hình trụ. Có màu trắng, vàng, không lẫn các tạp chất dễ thấy như lá cây, vỏ cây, sợi PP, kim loại, côn trùng, đất cát và các tạp chất khác
A35: Grade 1 :FGC characteristics: Shape :conform to the Shape of container(cup, buckest). Color :White, Yellow. Impurities : No no visible impurities such as leaves, bark, PP fibers, metal, insects, dirt, sand, or other foreign matter
A36: KĐ: Không đạt - mủ loại 2 không đạt chất lượng : Có hình dáng theo dụng cụ chứa (chén, thùng) thường là hình trụ. Có lẫn các tạp chất dễ thấy như lá cây, vỏ cây, sợi PP, kim loại, côn trùng, đất cát và các tạp chất khác.
A37: Grade 2 :FGC characteristics: Shape :conform to the Shape of container(cup, buckest). . Impurities: It contains visible impurities such as leaves, bark, PP fibers, metal, insects, dirt, sand, and other foreign matte
A38: …………….……….....………..….…………………..……………...…………..…………………………...……..…………...………………………………..........................................................................................................................................................................................................................................
A39: …………….……….....………..….…………………..……………...…………..…………………………...……..…………...………………………………..........................................................................................................................................................................................................................................
A40: …………….……….....………..….…………………..……………...…………..…………………………...……..…………...………………………………..........................................................................................................................................................................................................................................
A43: Yield for the month 1/2026 / SẢN LƯỢNG THÁNG 1 NĂM 2026
A44: No. | B44: Forest Plot Code | C44: Name of Plot | D44: Full Name | E44: Employee ID | F44: Date / Ngày ........... | H44: Date / Ngày ........... | J44: Date / Ngày ........... | L44: Date / Ngày ........... | N44: Date / Ngày ........... | P44: Date / Ngày ........... | R44: Date / Ngày ........... | T44: Date / Ngày ........... | V44: Total Days
V45: TỔNG 0 NGÀY
A46: STT | B46: Mã lô rừng | C46: Tên lô | D46: HỌ VÀ TÊN | E46: Mã số CN | F46: Tapp. Session/ Phiên cạo C | H46: Tapp. Session/ Phiên cạo C | J46: Tapp. Session/ Phiên cạo C | L46: Tapp. Session/ Phiên cạo C | N46: Tapp. Session/ Phiên cạo C | P46: Tapp. Session/ Phiên cạo C | R46: Tapp. Session/ Phiên cạo C | T46: Tapp. Session/ Phiên cạo C | V46: From…..top …...
V47: (Từ ngày…...đến ngày.…..)
F48: Cup Lump | H48: Cup Lump | J48: Cup Lump | L48: Cup Lump | N48: Cup Lump | P48: Cup Lump | R48: Cup Lump | T48: Cup Lump | V48: Cup Lump
...

Sheet T4
A1: Yield for the month 1/2026 / SẢN LƯỢNG THÁNG 1 NĂM 2026
A2: No. | B2: Forest Plot Code | C2: Name of Plot | D2: Full Name | E2: Employee ID | F2: Date / Ngày ........... | H2: Date / Ngày ........... | J2: Date / Ngày ........... | L2: Date / Ngày ........... | N2: Date / Ngày ........... | P2: Date / Ngày ........... | R2: Date / Ngày ........... | T2: Date / Ngày ........... | V2: Total Days
V3: TỔNG 0 NGÀY
A4: STT | B4: Mã lô rừng | C4: Tên lô | D4: HỌ VÀ TÊN | E4: Mã số CN | F4: Tapp. Session/ Phiên cạo A | H4: Tapp. Session/ Phiên cạo A | J4: Tapp. Session/ Phiên cạo A | L4: Tapp. Session/ Phiên cạo A | N4: Tapp. Session/ Phiên cạo A | P4: Tapp. Session/ Phiên cạo A | R4: Tapp. Session/ Phiên cạo A | T4: Tapp. Session/ Phiên cạo A | V4: From…..top …...
V5: (Từ ngày…...đến ngày.…..)
F6: Cup Lump | H6: Cup Lump | J6: Cup Lump | L6: Cup Lump | N6: Cup Lump | P6: Cup Lump | R6: Cup Lump | T6: Cup Lump | V6: Cup Lump
F7: Mủ đông | H7: Mủ đông | J7: Mủ đông | L7: Mủ đông | N7: Mủ đông | P7: Mủ đông | R7: Mủ đông | T7: Mủ đông | V7: Mủ đông
V8: =SUM(F8:U8)
A9: Total / TC | F9: =SUM(F8:F8) | H9: =SUM(H8:H8) | J9: =SUM(J8:J8) | L9: =SUM(L8:L8) | N9: =SUM(N8:N8) | P9: =SUM(P8:P8) | R9: =SUM(R8:R8) | T9: =SUM(T8:T8) | V9: =SUBTOTAL(9,V8:V8)
A11: Notes/ GHI CHÚ:
A13: Đ: Đạt - mủ loại 1 đạt chất lượng : Có hình dáng theo dụng cụ chứa (chén, thùng) thường là hình trụ. Có màu trắng, vàng, không lẫn các tạp chất dễ thấy như lá cây, vỏ cây, sợi PP, kim loại, côn trùng, đất cát và các tạp chất khác
A14: Grade 1 :FGC characteristics: Shape :conform to the Shape of container(cup, buckest). Color :White, Yellow. Impurities : No no visible impurities such as leaves, bark, PP fibers, metal, insects, dirt, sand, or other foreign matter
A15: KĐ: Không đạt - mủ loại 2 không đạt chất lượng : Có hình dáng theo dụng cụ chứa (chén, thùng) thường là hình trụ. Có lẫn các tạp chất dễ thấy như lá cây, vỏ cây, sợi PP, kim loại, côn trùng, đất cát và các tạp chất khác.
A16: Grade 2 :FGC characteristics: Shape :conform to the Shape of container(cup, buckest). . Impurities: It contains visible impurities such as leaves, bark, PP fibers, metal, insects, dirt, sand, and other foreign matte
A17: …………….……….....………..….…………………..……………...…………..…………………………...……..…………...………………………………..........................................................................................................................................................................................................................................
A18: …………….……….....………..….…………………..……………...…………..…………………………...……..…………...………………………………..........................................................................................................................................................................................................................................
A19: …………….……….....………..….…………………..……………...…………..…………………………...……..…………...………………………………..........................................................................................................................................................................................................................................
A22: Yield for the month 1/2026 / SẢN LƯỢNG THÁNG 1 NĂM 2026
A23: No. | B23: Forest Plot Code | C23: Name of Plot | D23: Full Name | E23: Employee ID | F23: Date / Ngày ........... | H23: Date / Ngày ........... | J23: Date / Ngày ........... | L23: Date / Ngày ........... | N23: Date / Ngày ........... | P23: Date / Ngày ........... | R23: Date / Ngày ........... | T23: Date / Ngày ........... | V23: Total Days
V24: TỔNG 0 NGÀY
A25: STT | B25: Mã lô rừng | C25: Tên lô | D25: HỌ VÀ TÊN | E25: Mã số CN | F25: Tapp. Session/ Phiên cạo B | H25: Tapp. Session/ Phiên cạo B | J25: Tapp. Session/ Phiên cạo B | L25: Tapp. Session/ Phiên cạo B | N25: Tapp. Session/ Phiên cạo B | P25: Tapp. Session/ Phiên cạo B | R25: Tapp. Session/ Phiên cạo B | T25: Tapp. Session/ Phiên cạo B | V25: From…..top …...
V26: (Từ ngày…...đến ngày.…..)
F27: Cup Lump | H27: Cup Lump | J27: Cup Lump | L27: Cup Lump | N27: Cup Lump | P27: Cup Lump | R27: Cup Lump | T27: Cup Lump | V27: Cup Lump
F28: Mủ đông | H28: Mủ đông | J28: Mủ đông | L28: Mủ đông | N28: Mủ đông | P28: Mủ đông | R28: Mủ đông | T28: Mủ đông | V28: Mủ đông
V29: =SUM(F29:U29)
A30: Total / TC | F30: =SUM(F29:F29) | H30: =SUM(H29:H29) | J30: =SUM(J29:J29) | L30: =SUM(L29:L29) | N30: =SUM(N29:N29) | P30: =SUM(P29:P29) | R30: =SUM(R29:R29) | T30: =SUM(T29:T29) | V30: =SUBTOTAL(9,V29:V29)
A32: Notes/ GHI CHÚ:
A34: Đ: Đạt - mủ loại 1 đạt chất lượng : Có hình dáng theo dụng cụ chứa (chén, thùng) thường là hình trụ. Có màu trắng, vàng, không lẫn các tạp chất dễ thấy như lá cây, vỏ cây, sợi PP, kim loại, côn trùng, đất cát và các tạp chất khác
A35: Grade 1 :FGC characteristics: Shape :conform to the Shape of container(cup, buckest). Color :White, Yellow. Impurities : No no visible impurities such as leaves, bark, PP fibers, metal, insects, dirt, sand, or other foreign matter
A36: KĐ: Không đạt - mủ loại 2 không đạt chất lượng : Có hình dáng theo dụng cụ chứa (chén, thùng) thường là hình trụ. Có lẫn các tạp chất dễ thấy như lá cây, vỏ cây, sợi PP, kim loại, côn trùng, đất cát và các tạp chất khác.
A37: Grade 2 :FGC characteristics: Shape :conform to the Shape of container(cup, buckest). . Impurities: It contains visible impurities such as leaves, bark, PP fibers, metal, insects, dirt, sand, and other foreign matte
A38: …………….……….....………..….…………………..……………...…………..…………………………...……..…………...………………………………..........................................................................................................................................................................................................................................
A39: …………….……….....………..….…………………..……………...…………..…………………………...……..…………...………………………………..........................................................................................................................................................................................................................................
A40: …………….……….....………..….…………………..……………...…………..…………………………...……..…………...………………………………..........................................................................................................................................................................................................................................
A43: Yield for the month 1/2026 / SẢN LƯỢNG THÁNG 1 NĂM 2026
A44: No. | B44: Forest Plot Code | C44: Name of Plot | D44: Full Name | E44: Employee ID | F44: Date / Ngày ........... | H44: Date / Ngày ........... | J44: Date / Ngày ........... | L44: Date / Ngày ........... | N44: Date / Ngày ........... | P44: Date / Ngày ........... | R44: Date / Ngày ........... | T44: Date / Ngày ........... | V44: Total Days
V45: TỔNG 0 NGÀY
A46: STT | B46: Mã lô rừng | C46: Tên lô | D46: HỌ VÀ TÊN | E46: Mã số CN | F46: Tapp. Session/ Phiên cạo C | H46: Tapp. Session/ Phiên cạo C | J46: Tapp. Session/ Phiên cạo C | L46: Tapp. Session/ Phiên cạo C | N46: Tapp. Session/ Phiên cạo C | P46: Tapp. Session/ Phiên cạo C | R46: Tapp. Session/ Phiên cạo C | T46: Tapp. Session/ Phiên cạo C | V46: From…..top …...
V47: (Từ ngày…...đến ngày.…..)
F48: Cup Lump | H48: Cup Lump | J48: Cup Lump | L48: Cup Lump | N48: Cup Lump | P48: Cup Lump | R48: Cup Lump | T48: Cup Lump | V48: Cup Lump
...

Sheet T5
A1: Yield for the month 1/2026 / SẢN LƯỢNG THÁNG 1 NĂM 2026
A2: No. | B2: Forest Plot Code | C2: Name of Plot | D2: Full Name | E2: Employee ID | F2: Date / Ngày ........... | H2: Date / Ngày ........... | J2: Date / Ngày ........... | L2: Date / Ngày ........... | N2: Date / Ngày ........... | P2: Date / Ngày ........... | R2: Date / Ngày ........... | T2: Date / Ngày ........... | V2: Total Days
V3: TỔNG 0 NGÀY
A4: STT | B4: Mã lô rừng | C4: Tên lô | D4: HỌ VÀ TÊN | E4: Mã số CN | F4: Tapp. Session/ Phiên cạo A | H4: Tapp. Session/ Phiên cạo A | J4: Tapp. Session/ Phiên cạo A | L4: Tapp. Session/ Phiên cạo A | N4: Tapp. Session/ Phiên cạo A | P4: Tapp. Session/ Phiên cạo A | R4: Tapp. Session/ Phiên cạo A | T4: Tapp. Session/ Phiên cạo A | V4: From…..top …...
V5: (Từ ngày…...đến ngày.…..)
F6: Cup Lump | H6: Cup Lump | J6: Cup Lump | L6: Cup Lump | N6: Cup Lump | P6: Cup Lump | R6: Cup Lump | T6: Cup Lump | V6: Cup Lump
F7: Mủ đông | H7: Mủ đông | J7: Mủ đông | L7: Mủ đông | N7: Mủ đông | P7: Mủ đông | R7: Mủ đông | T7: Mủ đông | V7: Mủ đông
V8: =SUM(F8:U8)
A9: Total / TC | F9: =SUM(F8:F8) | H9: =SUM(H8:H8) | J9: =SUM(J8:J8) | L9: =SUM(L8:L8) | N9: =SUM(N8:N8) | P9: =SUM(P8:P8) | R9: =SUM(R8:R8) | T9: =SUM(T8:T8) | V9: =SUBTOTAL(9,V8:V8)
A11: Notes/ GHI CHÚ:
A13: Đ: Đạt - mủ loại 1 đạt chất lượng : Có hình dáng theo dụng cụ chứa (chén, thùng) thường là hình trụ. Có màu trắng, vàng, không lẫn các tạp chất dễ thấy như lá cây, vỏ cây, sợi PP, kim loại, côn trùng, đất cát và các tạp chất khác
A14: Grade 1 :FGC characteristics: Shape :conform to the Shape of container(cup, buckest). Color :White, Yellow. Impurities : No no visible impurities such as leaves, bark, PP fibers, metal, insects, dirt, sand, or other foreign matter
A15: KĐ: Không đạt - mủ loại 2 không đạt chất lượng : Có hình dáng theo dụng cụ chứa (chén, thùng) thường là hình trụ. Có lẫn các tạp chất dễ thấy như lá cây, vỏ cây, sợi PP, kim loại, côn trùng, đất cát và các tạp chất khác.
A16: Grade 2 :FGC characteristics: Shape :conform to the Shape of container(cup, buckest). . Impurities: It contains visible impurities such as leaves, bark, PP fibers, metal, insects, dirt, sand, and other foreign matte
A17: …………….……….....………..….…………………..……………...…………..…………………………...……..…………...………………………………..........................................................................................................................................................................................................................................
A18: …………….……….....………..….…………………..……………...…………..…………………………...……..…………...………………………………..........................................................................................................................................................................................................................................
A19: …………….……….....………..….…………………..……………...…………..…………………………...……..…………...………………………………..........................................................................................................................................................................................................................................
A22: Yield for the month 1/2026 / SẢN LƯỢNG THÁNG 1 NĂM 2026
A23: No. | B23: Forest Plot Code | C23: Name of Plot | D23: Full Name | E23: Employee ID | F23: Date / Ngày ........... | H23: Date / Ngày ........... | J23: Date / Ngày ........... | L23: Date / Ngày ........... | N23: Date / Ngày ........... | P23: Date / Ngày ........... | R23: Date / Ngày ........... | T23: Date / Ngày ........... | V23: Total Days
V24: TỔNG 0 NGÀY
A25: STT | B25: Mã lô rừng | C25: Tên lô | D25: HỌ VÀ TÊN | E25: Mã số CN | F25: Tapp. Session/ Phiên cạo B | H25: Tapp. Session/ Phiên cạo B | J25: Tapp. Session/ Phiên cạo B | L25: Tapp. Session/ Phiên cạo B | N25: Tapp. Session/ Phiên cạo B | P25: Tapp. Session/ Phiên cạo B | R25: Tapp. Session/ Phiên cạo B | T25: Tapp. Session/ Phiên cạo B | V25: From…..top …...
V26: (Từ ngày…...đến ngày.…..)
F27: Cup Lump | H27: Cup Lump | J27: Cup Lump | L27: Cup Lump | N27: Cup Lump | P27: Cup Lump | R27: Cup Lump | T27: Cup Lump | V27: Cup Lump
F28: Mủ đông | H28: Mủ đông | J28: Mủ đông | L28: Mủ đông | N28: Mủ đông | P28: Mủ đông | R28: Mủ đông | T28: Mủ đông | V28: Mủ đông
V29: =SUM(F29:U29)
A30: Total / TC | F30: =SUM(F29:F29) | H30: =SUM(H29:H29) | J30: =SUM(J29:J29) | L30: =SUM(L29:L29) | N30: =SUM(N29:N29) | P30: =SUM(P29:P29) | R30: =SUM(R29:R29) | T30: =SUM(T29:T29) | V30: =SUBTOTAL(9,V29:V29)
A32: Notes/ GHI CHÚ:
A34: Đ: Đạt - mủ loại 1 đạt chất lượng : Có hình dáng theo dụng cụ chứa (chén, thùng) thường là hình trụ. Có màu trắng, vàng, không lẫn các tạp chất dễ thấy như lá cây, vỏ cây, sợi PP, kim loại, côn trùng, đất cát và các tạp chất khác
A35: Grade 1 :FGC characteristics: Shape :conform to the Shape of container(cup, buckest). Color :White, Yellow. Impurities : No no visible impurities such as leaves, bark, PP fibers, metal, insects, dirt, sand, or other foreign matter
A36: KĐ: Không đạt - mủ loại 2 không đạt chất lượng : Có hình dáng theo dụng cụ chứa (chén, thùng) thường là hình trụ. Có lẫn các tạp chất dễ thấy như lá cây, vỏ cây, sợi PP, kim loại, côn trùng, đất cát và các tạp chất khác.
A37: Grade 2 :FGC characteristics: Shape :conform to the Shape of container(cup, buckest). . Impurities: It contains visible impurities such as leaves, bark, PP fibers, metal, insects, dirt, sand, and other foreign matte
A38: …………….……….....………..….…………………..……………...…………..…………………………...……..…………...………………………………..........................................................................................................................................................................................................................................
A39: …………….……….....………..….…………………..……………...…………..…………………………...……..…………...………………………………..........................................................................................................................................................................................................................................
A40: …………….……….....………..….…………………..……………...…………..…………………………...……..…………...………………………………..........................................................................................................................................................................................................................................
A43: Yield for the month 1/2026 / SẢN LƯỢNG THÁNG 1 NĂM 2026
A44: No. | B44: Forest Plot Code | C44: Name of Plot | D44: Full Name | E44: Employee ID | F44: Date / Ngày ........... | H44: Date / Ngày ........... | J44: Date / Ngày ........... | L44: Date / Ngày ........... | N44: Date / Ngày ........... | P44: Date / Ngày ........... | R44: Date / Ngày ........... | T44: Date / Ngày ........... | V44: Total Days
V45: TỔNG 0 NGÀY
A46: STT | B46: Mã lô rừng | C46: Tên lô | D46: HỌ VÀ TÊN | E46: Mã số CN | F46: Tapp. Session/ Phiên cạo C | H46: Tapp. Session/ Phiên cạo C | J46: Tapp. Session/ Phiên cạo C | L46: Tapp. Session/ Phiên cạo C | N46: Tapp. Session/ Phiên cạo C | P46: Tapp. Session/ Phiên cạo C | R46: Tapp. Session/ Phiên cạo C | T46: Tapp. Session/ Phiên cạo C | V46: From…..top …...
V47: (Từ ngày…...đến ngày.…..)
F48: Cup Lump | H48: Cup Lump | J48: Cup Lump | L48: Cup Lump | N48: Cup Lump | P48: Cup Lump | R48: Cup Lump | T48: Cup Lump | V48: Cup Lump
...

Sheet T6
A1: Yield for the month 1/2026 / SẢN LƯỢNG THÁNG 1 NĂM 2026
A2: No. | B2: Forest Plot Code | C2: Name of Plot | D2: Full Name | E2: Employee ID | F2: Date / Ngày ........... | H2: Date / Ngày ........... | J2: Date / Ngày ........... | L2: Date / Ngày ........... | N2: Date / Ngày ........... | P2: Date / Ngày ........... | R2: Date / Ngày ........... | T2: Date / Ngày ........... | V2: Total Days
V3: TỔNG 0 NGÀY
A4: STT | B4: Mã lô rừng | C4: Tên lô | D4: HỌ VÀ TÊN | E4: Mã số CN | F4: Tapp. Session/ Phiên cạo A | H4: Tapp. Session/ Phiên cạo A | J4: Tapp. Session/ Phiên cạo A | L4: Tapp. Session/ Phiên cạo A | N4: Tapp. Session/ Phiên cạo A | P4: Tapp. Session/ Phiên cạo A | R4: Tapp. Session/ Phiên cạo A | T4: Tapp. Session/ Phiên cạo A | V4: From…..top …...
V5: (Từ ngày…...đến ngày.…..)
F6: Cup Lump | H6: Cup Lump | J6: Cup Lump | L6: Cup Lump | N6: Cup Lump | P6: Cup Lump | R6: Cup Lump | T6: Cup Lump | V6: Cup Lump
F7: Mủ đông | H7: Mủ đông | J7: Mủ đông | L7: Mủ đông | N7: Mủ đông | P7: Mủ đông | R7: Mủ đông | T7: Mủ đông | V7: Mủ đông
V8: =SUM(F8:U8)
A9: Total / TC | F9: =SUM(F8:F8) | H9: =SUM(H8:H8) | J9: =SUM(J8:J8) | L9: =SUM(L8:L8) | N9: =SUM(N8:N8) | P9: =SUM(P8:P8) | R9: =SUM(R8:R8) | T9: =SUM(T8:T8) | V9: =SUBTOTAL(9,V8:V8)
A11: Notes/ GHI CHÚ:
A13: Đ: Đạt - mủ loại 1 đạt chất lượng : Có hình dáng theo dụng cụ chứa (chén, thùng) thường là hình trụ. Có màu trắng, vàng, không lẫn các tạp chất dễ thấy như lá cây, vỏ cây, sợi PP, kim loại, côn trùng, đất cát và các tạp chất khác
A14: Grade 1 :FGC characteristics: Shape :conform to the Shape of container(cup, buckest). Color :White, Yellow. Impurities : No no visible impurities such as leaves, bark, PP fibers, metal, insects, dirt, sand, or other foreign matter
A15: KĐ: Không đạt - mủ loại 2 không đạt chất lượng : Có hình dáng theo dụng cụ chứa (chén, thùng) thường là hình trụ. Có lẫn các tạp chất dễ thấy như lá cây, vỏ cây, sợi PP, kim loại, côn trùng, đất cát và các tạp chất khác.
A16: Grade 2 :FGC characteristics: Shape :conform to the Shape of container(cup, buckest). . Impurities: It contains visible impurities such as leaves, bark, PP fibers, metal, insects, dirt, sand, and other foreign matte
A17: …………….……….....………..….…………………..……………...…………..…………………………...……..…………...………………………………..........................................................................................................................................................................................................................................
A18: …………….……….....………..….…………………..……………...…………..…………………………...……..…………...………………………………..........................................................................................................................................................................................................................................
A19: …………….……….....………..….…………………..……………...…………..…………………………...……..…………...………………………………..........................................................................................................................................................................................................................................
A22: Yield for the month 1/2026 / SẢN LƯỢNG THÁNG 1 NĂM 2026
A23: No. | B23: Forest Plot Code | C23: Name of Plot | D23: Full Name | E23: Employee ID | F23: Date / Ngày ........... | H23: Date / Ngày ........... | J23: Date / Ngày ........... | L23: Date / Ngày ........... | N23: Date / Ngày ........... | P23: Date / Ngày ........... | R23: Date / Ngày ........... | T23: Date / Ngày ........... | V23: Total Days
V24: TỔNG 0 NGÀY
A25: STT | B25: Mã lô rừng | C25: Tên lô | D25: HỌ VÀ TÊN | E25: Mã số CN | F25: Tapp. Session/ Phiên cạo B | H25: Tapp. Session/ Phiên cạo B | J25: Tapp. Session/ Phiên cạo B | L25: Tapp. Session/ Phiên cạo B | N25: Tapp. Session/ Phiên cạo B | P25: Tapp. Session/ Phiên cạo B | R25: Tapp. Session/ Phiên cạo B | T25: Tapp. Session/ Phiên cạo B | V25: From…..top …...
V26: (Từ ngày…...đến ngày.…..)
F27: Cup Lump | H27: Cup Lump | J27: Cup Lump | L27: Cup Lump | N27: Cup Lump | P27: Cup Lump | R27: Cup Lump | T27: Cup Lump | V27: Cup Lump
F28: Mủ đông | H28: Mủ đông | J28: Mủ đông | L28: Mủ đông | N28: Mủ đông | P28: Mủ đông | R28: Mủ đông | T28: Mủ đông | V28: Mủ đông
V29: =SUM(F29:U29)
A30: Total / TC | F30: =SUM(F29:F29) | H30: =SUM(H29:H29) | J30: =SUM(J29:J29) | L30: =SUM(L29:L29) | N30: =SUM(N29:N29) | P30: =SUM(P29:P29) | R30: =SUM(R29:R29) | T30: =SUM(T29:T29) | V30: =SUBTOTAL(9,V29:V29)
A32: Notes/ GHI CHÚ:
A34: Đ: Đạt - mủ loại 1 đạt chất lượng : Có hình dáng theo dụng cụ chứa (chén, thùng) thường là hình trụ. Có màu trắng, vàng, không lẫn các tạp chất dễ thấy như lá cây, vỏ cây, sợi PP, kim loại, côn trùng, đất cát và các tạp chất khác
A35: Grade 1 :FGC characteristics: Shape :conform to the Shape of container(cup, buckest). Color :White, Yellow. Impurities : No no visible impurities such as leaves, bark, PP fibers, metal, insects, dirt, sand, or other foreign matter
A36: KĐ: Không đạt - mủ loại 2 không đạt chất lượng : Có hình dáng theo dụng cụ chứa (chén, thùng) thường là hình trụ. Có lẫn các tạp chất dễ thấy như lá cây, vỏ cây, sợi PP, kim loại, côn trùng, đất cát và các tạp chất khác.
A37: Grade 2 :FGC characteristics: Shape :conform to the Shape of container(cup, buckest). . Impurities: It contains visible impurities such as leaves, bark, PP fibers, metal, insects, dirt, sand, and other foreign matte
A38: …………….……….....………..….…………………..……………...…………..…………………………...……..…………...………………………………..........................................................................................................................................................................................................................................
A39: …………….……….....………..….…………………..……………...…………..…………………………...……..…………...………………………………..........................................................................................................................................................................................................................................
A40: …………….……….....………..….…………………..……………...…………..…………………………...……..…………...………………………………..........................................................................................................................................................................................................................................
A43: Yield for the month 1/2026 / SẢN LƯỢNG THÁNG 1 NĂM 2026
A44: No. | B44: Forest Plot Code | C44: Name of Plot | D44: Full Name | E44: Employee ID | F44: Date / Ngày ........... | H44: Date / Ngày ........... | J44: Date / Ngày ........... | L44: Date / Ngày ........... | N44: Date / Ngày ........... | P44: Date / Ngày ........... | R44: Date / Ngày ........... | T44: Date / Ngày ........... | V44: Total Days
V45: TỔNG 0 NGÀY
A46: STT | B46: Mã lô rừng | C46: Tên lô | D46: HỌ VÀ TÊN | E46: Mã số CN | F46: Tapp. Session/ Phiên cạo C | H46: Tapp. Session/ Phiên cạo C | J46: Tapp. Session/ Phiên cạo C | L46: Tapp. Session/ Phiên cạo C | N46: Tapp. Session/ Phiên cạo C | P46: Tapp. Session/ Phiên cạo C | R46: Tapp. Session/ Phiên cạo C | T46: Tapp. Session/ Phiên cạo C | V46: From…..top …...
V47: (Từ ngày…...đến ngày.…..)
F48: Cup Lump | H48: Cup Lump | J48: Cup Lump | L48: Cup Lump | N48: Cup Lump | P48: Cup Lump | R48: Cup Lump | T48: Cup Lump | V48: Cup Lump
...

Sheet T7
A1: Yield for the month 1/2026 / SẢN LƯỢNG THÁNG 1 NĂM 2026
A2: No. | B2: Forest Plot Code | C2: Name of Plot | D2: Full Name | E2: Employee ID | F2: Date / Ngày ........... | H2: Date / Ngày ........... | J2: Date / Ngày ........... | L2: Date / Ngày ........... | N2: Date / Ngày ........... | P2: Date / Ngày ........... | R2: Date / Ngày ........... | T2: Date / Ngày ........... | V2: Total Days
V3: TỔNG 0 NGÀY
A4: STT | B4: Mã lô rừng | C4: Tên lô | D4: HỌ VÀ TÊN | E4: Mã số CN | F4: Tapp. Session/ Phiên cạo A | H4: Tapp. Session/ Phiên cạo A | J4: Tapp. Session/ Phiên cạo A | L4: Tapp. Session/ Phiên cạo A | N4: Tapp. Session/ Phiên cạo A | P4: Tapp. Session/ Phiên cạo A | R4: Tapp. Session/ Phiên cạo A | T4: Tapp. Session/ Phiên cạo A | V4: From…..top …...
V5: (Từ ngày…...đến ngày.…..)
F6: Cup Lump | H6: Cup Lump | J6: Cup Lump | L6: Cup Lump | N6: Cup Lump | P6: Cup Lump | R6: Cup Lump | T6: Cup Lump | V6: Cup Lump
F7: Mủ đông | H7: Mủ đông | J7: Mủ đông | L7: Mủ đông | N7: Mủ đông | P7: Mủ đông | R7: Mủ đông | T7: Mủ đông | V7: Mủ đông
V8: =SUM(F8:U8)
A9: Total / TC | F9: =SUM(F8:F8) | H9: =SUM(H8:H8) | J9: =SUM(J8:J8) | L9: =SUM(L8:L8) | N9: =SUM(N8:N8) | P9: =SUM(P8:P8) | R9: =SUM(R8:R8) | T9: =SUM(T8:T8) | V9: =SUBTOTAL(9,V8:V8)
A11: Notes/ GHI CHÚ:
A13: Đ: Đạt - mủ loại 1 đạt chất lượng : Có hình dáng theo dụng cụ chứa (chén, thùng) thường là hình trụ. Có màu trắng, vàng, không lẫn các tạp chất dễ thấy như lá cây, vỏ cây, sợi PP, kim loại, côn trùng, đất cát và các tạp chất khác
A14: Grade 1 :FGC characteristics: Shape :conform to the Shape of container(cup, buckest). Color :White, Yellow. Impurities : No no visible impurities such as leaves, bark, PP fibers, metal, insects, dirt, sand, or other foreign matter
A15: KĐ: Không đạt - mủ loại 2 không đạt chất lượng : Có hình dáng theo dụng cụ chứa (chén, thùng) thường là hình trụ. Có lẫn các tạp chất dễ thấy như lá cây, vỏ cây, sợi PP, kim loại, côn trùng, đất cát và các tạp chất khác.
A16: Grade 2 :FGC characteristics: Shape :conform to the Shape of container(cup, buckest). . Impurities: It contains visible impurities such as leaves, bark, PP fibers, metal, insects, dirt, sand, and other foreign matte
A17: …………….……….....………..….…………………..……………...…………..…………………………...……..…………...………………………………..........................................................................................................................................................................................................................................
A18: …………….……….....………..….…………………..……………...…………..…………………………...……..…………...………………………………..........................................................................................................................................................................................................................................
A19: …………….……….....………..….…………………..……………...…………..…………………………...……..…………...………………………………..........................................................................................................................................................................................................................................
A22: Yield for the month 1/2026 / SẢN LƯỢNG THÁNG 1 NĂM 2026
A23: No. | B23: Forest Plot Code | C23: Name of Plot | D23: Full Name | E23: Employee ID | F23: Date / Ngày ........... | H23: Date / Ngày ........... | J23: Date / Ngày ........... | L23: Date / Ngày ........... | N23: Date / Ngày ........... | P23: Date / Ngày ........... | R23: Date / Ngày ........... | T23: Date / Ngày ........... | V23: Total Days
V24: TỔNG 0 NGÀY
A25: STT | B25: Mã lô rừng | C25: Tên lô | D25: HỌ VÀ TÊN | E25: Mã số CN | F25: Tapp. Session/ Phiên cạo B | H25: Tapp. Session/ Phiên cạo B | J25: Tapp. Session/ Phiên cạo B | L25: Tapp. Session/ Phiên cạo B | N25: Tapp. Session/ Phiên cạo B | P25: Tapp. Session/ Phiên cạo B | R25: Tapp. Session/ Phiên cạo B | T25: Tapp. Session/ Phiên cạo B | V25: From…..top …...
V26: (Từ ngày…...đến ngày.…..)
F27: Cup Lump | H27: Cup Lump | J27: Cup Lump | L27: Cup Lump | N27: Cup Lump | P27: Cup Lump | R27: Cup Lump | T27: Cup Lump | V27: Cup Lump
F28: Mủ đông | H28: Mủ đông | J28: Mủ đông | L28: Mủ đông | N28: Mủ đông | P28: Mủ đông | R28: Mủ đông | T28: Mủ đông | V28: Mủ đông
V29: =SUM(F29:U29)
A30: Total / TC | F30: =SUM(F29:F29) | H30: =SUM(H29:H29) | J30: =SUM(J29:J29) | L30: =SUM(L29:L29) | N30: =SUM(N29:N29) | P30: =SUM(P29:P29) | R30: =SUM(R29:R29) | T30: =SUM(T29:T29) | V30: =SUBTOTAL(9,V29:V29)
A32: Notes/ GHI CHÚ:
A34: Đ: Đạt - mủ loại 1 đạt chất lượng : Có hình dáng theo dụng cụ chứa (chén, thùng) thường là hình trụ. Có màu trắng, vàng, không lẫn các tạp chất dễ thấy như lá cây, vỏ cây, sợi PP, kim loại, côn trùng, đất cát và các tạp chất khác
A35: Grade 1 :FGC characteristics: Shape :conform to the Shape of container(cup, buckest). Color :White, Yellow. Impurities : No no visible impurities such as leaves, bark, PP fibers, metal, insects, dirt, sand, or other foreign matter
A36: KĐ: Không đạt - mủ loại 2 không đạt chất lượng : Có hình dáng theo dụng cụ chứa (chén, thùng) thường là hình trụ. Có lẫn các tạp chất dễ thấy như lá cây, vỏ cây, sợi PP, kim loại, côn trùng, đất cát và các tạp chất khác.
A37: Grade 2 :FGC characteristics: Shape :conform to the Shape of container(cup, buckest). . Impurities: It contains visible impurities such as leaves, bark, PP fibers, metal, insects, dirt, sand, and other foreign matte
A38: …………….……….....………..….…………………..……………...…………..…………………………...……..…………...………………………………..........................................................................................................................................................................................................................................
A39: …………….……….....………..….…………………..……………...…………..…………………………...……..…………...………………………………..........................................................................................................................................................................................................................................
A40: …………….……….....………..….…………………..……………...…………..…………………………...……..…………...………………………………..........................................................................................................................................................................................................................................
A43: Yield for the month 1/2026 / SẢN LƯỢNG THÁNG 1 NĂM 2026
A44: No. | B44: Forest Plot Code | C44: Name of Plot | D44: Full Name | E44: Employee ID | F44: Date / Ngày ........... | H44: Date / Ngày ........... | J44: Date / Ngày ........... | L44: Date / Ngày ........... | N44: Date / Ngày ........... | P44: Date / Ngày ........... | R44: Date / Ngày ........... | T44: Date / Ngày ........... | V44: Total Days
V45: TỔNG 0 NGÀY
A46: STT | B46: Mã lô rừng | C46: Tên lô | D46: HỌ VÀ TÊN | E46: Mã số CN | F46: Tapp. Session/ Phiên cạo C | H46: Tapp. Session/ Phiên cạo C | J46: Tapp. Session/ Phiên cạo C | L46: Tapp. Session/ Phiên cạo C | N46: Tapp. Session/ Phiên cạo C | P46: Tapp. Session/ Phiên cạo C | R46: Tapp. Session/ Phiên cạo C | T46: Tapp. Session/ Phiên cạo C | V46: From…..top …...
V47: (Từ ngày…...đến ngày.…..)
F48: Cup Lump | H48: Cup Lump | J48: Cup Lump | L48: Cup Lump | N48: Cup Lump | P48: Cup Lump | R48: Cup Lump | T48: Cup Lump | V48: Cup Lump
...

Sheet T8
A1: Yield for the month 1/2026 / SẢN LƯỢNG THÁNG 1 NĂM 2026
A2: No. | B2: Forest Plot Code | C2: Name of Plot | D2: Full Name | E2: Employee ID | F2: Date / Ngày ........... | H2: Date / Ngày ........... | J2: Date / Ngày ........... | L2: Date / Ngày ........... | N2: Date / Ngày ........... | P2: Date / Ngày ........... | R2: Date / Ngày ........... | T2: Date / Ngày ........... | V2: Total Days
V3: TỔNG 0 NGÀY
A4: STT | B4: Mã lô rừng | C4: Tên lô | D4: HỌ VÀ TÊN | E4: Mã số CN | F4: Tapp. Session/ Phiên cạo A | H4: Tapp. Session/ Phiên cạo A | J4: Tapp. Session/ Phiên cạo A | L4: Tapp. Session/ Phiên cạo A | N4: Tapp. Session/ Phiên cạo A | P4: Tapp. Session/ Phiên cạo A | R4: Tapp. Session/ Phiên cạo A | T4: Tapp. Session/ Phiên cạo A | V4: From…..top …...
V5: (Từ ngày…...đến ngày.…..)
F6: Cup Lump | H6: Cup Lump | J6: Cup Lump | L6: Cup Lump | N6: Cup Lump | P6: Cup Lump | R6: Cup Lump | T6: Cup Lump | V6: Cup Lump
F7: Mủ đông | H7: Mủ đông | J7: Mủ đông | L7: Mủ đông | N7: Mủ đông | P7: Mủ đông | R7: Mủ đông | T7: Mủ đông | V7: Mủ đông
V8: =SUM(F8:U8)
A9: Total / TC | F9: =SUM(F8:F8) | H9: =SUM(H8:H8) | J9: =SUM(J8:J8) | L9: =SUM(L8:L8) | N9: =SUM(N8:N8) | P9: =SUM(P8:P8) | R9: =SUM(R8:R8) | T9: =SUM(T8:T8) | V9: =SUBTOTAL(9,V8:V8)
A11: Notes/ GHI CHÚ:
A13: Đ: Đạt - mủ loại 1 đạt chất lượng : Có hình dáng theo dụng cụ chứa (chén, thùng) thường là hình trụ. Có màu trắng, vàng, không lẫn các tạp chất dễ thấy như lá cây, vỏ cây, sợi PP, kim loại, côn trùng, đất cát và các tạp chất khác
A14: Grade 1 :FGC characteristics: Shape :conform to the Shape of container(cup, buckest). Color :White, Yellow. Impurities : No no visible impurities such as leaves, bark, PP fibers, metal, insects, dirt, sand, or other foreign matter
A15: KĐ: Không đạt - mủ loại 2 không đạt chất lượng : Có hình dáng theo dụng cụ chứa (chén, thùng) thường là hình trụ. Có lẫn các tạp chất dễ thấy như lá cây, vỏ cây, sợi PP, kim loại, côn trùng, đất cát và các tạp chất khác.
A16: Grade 2 :FGC characteristics: Shape :conform to the Shape of container(cup, buckest). . Impurities: It contains visible impurities such as leaves, bark, PP fibers, metal, insects, dirt, sand, and other foreign matte
A17: …………….……….....………..….…………………..……………...…………..…………………………...……..…………...………………………………..........................................................................................................................................................................................................................................
A18: …………….……….....………..….…………………..……………...…………..…………………………...……..…………...………………………………..........................................................................................................................................................................................................................................
A19: …………….……….....………..….…………………..……………...…………..…………………………...……..…………...………………………………..........................................................................................................................................................................................................................................
A22: Yield for the month 1/2026 / SẢN LƯỢNG THÁNG 1 NĂM 2026
A23: No. | B23: Forest Plot Code | C23: Name of Plot | D23: Full Name | E23: Employee ID | F23: Date / Ngày ........... | H23: Date / Ngày ........... | J23: Date / Ngày ........... | L23: Date / Ngày ........... | N23: Date / Ngày ........... | P23: Date / Ngày ........... | R23: Date / Ngày ........... | T23: Date / Ngày ........... | V23: Total Days
V24: TỔNG 0 NGÀY
